# 具体类型错误和无类型错误

上节代码中的 do/catch 有些地方乍一看并不是非常合适。即使我们非常确定所有可能发生的错误都是 ParseError 类型的，并且，我们也逐一处理了它的每一个 case，编译器还是需要我们在最后写一个捕获所有异常的 catch all以确认所有可能的错误都被处理了。

这是因为 Swift 原生的错误处理机制使用了无类型错误 (untyped errors)。我们只能用 throws 声明函数会抛出错误，但无法指定它究竟会抛出哪些具体的错误。因此，为了从语言层面确保所有错误都可以被处理，编译器才总是要求我们编写一个 catchall 语句。在错误处理系统中使用无类型错误是 Swift 核心团队刻意为之的。原因是在大部分情况下，巨细无遗的错误处理是不现实也没必要的。通常，你可能只关心一两个特定的错误情况，然后给其它错误在 catchall 语句中提供一个通用的处理方法就好了。

而之前介绍过的 Result，则属于具体类型错误 (typed errors)。Result 带有两个泛型参数，Success 和 Failure，而后者指定了错误的具体类型。正是这种结构，才让我们最早实现 contents(ofFile:) 的时候，可以通过遍历 `Result<String, FileError>` 中的 FileError，处理每一种错误。


## 不可忽略的错误

在这一章的介绍中，我们把安全性作为了判断一个优质错误处理系统的因素。使用内建错误处理的一个很大的好处，就是当你调用一个可能会抛出错误的方法时，编译器不会让你忽略掉这些错误。但使用 Result，情况就不会总是如此了。

例如，考虑 Foundation 中的 Data.write(to:options:) 方法 (向文件中写入若干字节) 或 FileManager.removeItem(at:) 方法 (删除指定文件)：
```
extension Data {
	func write(to url: URL, options: Data.WritingOptions = []) throws
}
extension FileManager {
	func removeItem(at URL: URL) throws
}
```
这些方法的特别之处就是我们是为了它们的副作用而调用它们的，而不是为了返回值。实际上，除了表示操作是否成功之外，这两个方法都没有一个真正有意义的返回值。所以，上面这两个 Result 的版本，无论是否是故意的，对于程序员来说，都太容易忽略掉任何失败的情况了，他们可能会直接写出下面的代码：
`_ = FileManager.default.removeItem(at: url)`

而调用 throws 版本的时候，编译器会强制我们在调用前面使用 try 前缀。编译器还会要求我们要么把调用嵌套在一个 do/catch 代码块里，要么把错误传递到调用栈的上层。无论是对写这段代码的程序员，还是这段代码的读者，这都是一个明确清晰的提示：当前调用的函数是有可能执行失败的，编译器会强制要求我们处理相关的错误。


## 错误在 throws 和 Optionals 之间转换

当把一个函数的结果传递给其它 API 时，在可抛出错误的函数和返回可选值的函数之间，难免我们还要在这两种表达错误的形式之间来回转换。

try? 关键字允许我们忽略函数抛出的错误，并把函数的返回值变成包含原始返回值的 Optional。这个 Optional 可以告诉我们函数是否执行成功了。

```
if let result = try? parse(text: input) {
	print(result)
}
```
使用 try? 意味着我们将比之前获得更少的错误信息，我们唯一知道的，就是函数究竟是执行成功了，还是发生了某些错误，至于和错误相关的具体信息，则已经被丢掉无法找回了。类似的，为了把一个返回 Optional 的函数变成一个抛出错误的函数，我们得为 nil 提供相应的错误值。下面是个 Optional 的扩展，它会对自己解包，并且当自身为 nil 时，抛出一个错误：
```
extension Optional {
	/// 如果是非 `nil` 值，就对 `self` 解包。
	/// 如果 `self` 是 `nil`，就抛出错误。
	func or(error: Error) throws -> Wrapped {
		switch self {
		case let x?: return x
		case nil: throw error
		}
	}
}
//这个扩展的用法
do {
	let int = try Int("42").or(error: ReadIntError.couldNotRead)
} catch {
	print(error)
}
```
try? 关键字的存在可能会引起一些争议，毕竟它和 Swift 不允许忽略错误的哲学相违背。但说到底，你还是要明确使用 try? 关键字，这也可以看作是编译器强制你对错误进行的某种响应，而代码的读者，也可以通过 try? 明确你的意图。因此，当你对错误信息完全不感兴趣的时候，try? 是一种合理的选择。

try 还有第三种形式：try!。只有你确认函数绝对不可能发生错误的时候，才应该使用这种形式。和强制解包一个 nil 的 Optional 值类似，如果在运行时你的假设发生了错误，那么使用 try! 就会造成程序崩溃。


## 错误在 throws 和 Result 之间转换

为了调用一个可抛出错误的函数，并把它的返回值包装成一个 Result，可以使用 init(catching:) 初始化方法，它接受一个可抛出错误的函数作为参数，并把这个函数的返回值包装成Result 对象。它的实现是这样的：

```
//swift 5.6中系统已经实现
extension Result where Failure == Swift.Error {
	/// 通过评估一个可抛出错误的函数的返回值创建一个新的 `Result` 对象，
	/// 把成功的返回结果包装在 `case success` 里，而失败时抛出的错误
	/// 则包装在 `case failure`里。
	init(catching body: () throws -> Success) {
		do {
			self = .success(try body())
		} catch {
			self = .failure(error)
		}
	}
}

//这个初始化方法用起来是这样的：
let encoder = JSONEncoder()
let encodingResult = Result { try encoder.encode([1, 2]) } // success(5 bytes)
type(of: encodingResult) // Result<Data, Error>
```
如果你想延迟处理错误，或者把函数的返回结果发送给其它函数，这个方法就会非常有用了。

和 init(catching:) 相反的方法叫做 Result.get()。它会评估 Result 的结果，并把 failure 中的值作为错误抛出。它的实现在这里：
```
extension Result {
	public func get() throws -> Success {
		switch self {
		case let .success(success):
			return success
		case let .failure(failure):
			throw failure
		}
	}
}
```
