# 错误处理3-错误链和回调


## 错误链-throws链

接连调用多个可能抛出错误的函数是很普遍的情况。例如，一个操作可能被分成多个子任务，每一个子任务的输出都是下一个子任务的输入。如果每个子任务都可能执行失败，一旦其中一个抛出错误，整个操作就应该立即退出。

在 Swift 内建错误处理机制之下就很简单了，我们不需要使用嵌套的 if 语句或者类似的结构来保证代码运行，只要简单地将这些函数调用放到一个 do/catch 代码块中 (或者封装到一个被标记为 throws 的函数中) 就好了。当遇到第一个错误时，调用链将结束，代码将被切换到 catch 块中，或者传递到上层调用者去。
```
//下面这个例子，是个拥有三个子任务的操作：
func complexOperation(filename: String) throws -> [String] {
	let text = try contents(ofFile: filename)
	let segments = try parse(text: text)
	return try process(segments: segments)
}
```


## 错误链-result链

让我们把基于 try 的例子和与之等价的使用 Result 的代码进行一次对比。将多个返回 Result 的函数手动链接起来需要很多努力。我们需要调用第一个函数，解包它的输出，如果遇到的是 .success，则将值传递给下一个函数重新开始这个过程。一旦函数返回了 .failure，则需要将链打断，放弃接下来的所有调用，并将这个失败返回给调用者.

这种用法就会让代码变得一团糟，因为每串联一个返回 Result 的函数，就需要一层额外的 switch 语句嵌套，并且，还要重复一遍相同的错误处理语句。

幸运的是，Result 已经提供了解决办法。Result.flatMap 方法封装了这种根据 Result 结果决定是要继续向下个环节传递成功值，还是由于失败必须退出调用链的模式。它的结构和我们在可选值这一章中提到的 flatMap 是一样的。
```
func complexOperation2(filename: String) -> Result<[String], Error> {
	return contents(ofFile: filename).mapError { $0 as Error }
		.flatMap { text in 
			parse(text: text).mapError { $0 as Error }
		}
		.flatMap { segments in
			process(segments: segments).mapError { $0 as Error }
		}
}
```

要注意，我们还是得处理不兼容的错误类型。Result.flatMap 只会转换执行成功的结果，并保持 failure 的情况不变。因此串联多个 map 或者 flatMap 就要求 Result 中的 Failure 类型是相同的。在我们的例子中，这是通过不断调用 mapError 完成的，它们的任务就是把具体的错误类型泛化成“一个实现了 Error 的类型.


## 错误和回调

Swift 的内建错误处理和使用 async/await 模型的异步 API 有着紧密的结合：到目前为止我们所讨论过的内容，都可以等效地运用在 async 函数和方法上。不过内建的错误处理机制无法和通过基于回调的异步 API 搭配在一起工作。让我们看个异步大数计算的例子，它通过回调函数在计算完成后通知结果：
```
func compute(callback: (Int) -> ())

compute { number in
	print(number)
}

//用optional的方式返回错误
func computeOptional(callback: (Int?) -> ())

computeOptional { numberOrNil in
	print(numberOrNil ?? -1)
}
```

也不可以写成如下，这个签名有着完全不同的含义。它并不表明计算大数的方法会执行失败，而是表示回调函数自身可能发生错误。我们把上面的回调函数用返回 Result 的形式写出来，问题就清楚多了
```
func computeThrows(callback: (Int) throws -> ())
//同理
func computeResult(callback: (Int) -> Result<(), Error>)
```

只能如下做法
`func computeResult(callback: (Result<Int, Error>) -> ())`

Swift 内建错误处理机制对异步 API 的不兼容，体现了使用 throws 和使用 Optional 或 Result 处理错误时的一个关键区别。只有后者才可以自由地传递错误信息，而 throws 反而不那么灵活。对此，Joshua Emmons 非常形象地解释了这个区别：throw 和 return 很像，它只能沿着一个方向工作，也就是向上传递消息。我们可以把错误抛给函数的调用者，但不能把错误向下作为参数抛给接下来会调用的其它函数。
