# 错误处理

我们知道：编写错误处理相关的代码会很杂乱，而实现正确逻辑的代码则有趣得多。因此，编程语言自身可以为程序员提供一个良好的模型来支持这项任务，就显得更为重要了。以下是我们认为的，带有 throw、try 和 catch 的 Swift 内建错误处理架构所应该具备的一些特征：

+ 安全 (Safety)：Swift 让程序员无法出于意外的原因而忽略错误处理。
+ 简洁 (Conciseness)：不应该让逻辑正确的代码淹没在抛出和捕获错误的代码里。
+ 通用 (Universality)：错误抛出和处理的机制可以用于包括异步代码在内的所有场景。新的 async/await 异步函数模式完全支持基于 throw/try 的错误处理方式。
+ 可传递 (Propagation)：错误不一定要在发生的原地进行处理，因为通常从一个错误中恢复的逻辑，会远离错误发生的地方。Swift 的错误处理架构可以很容易让错误沿着调用栈向上传递到合适的位置。
+ 文档 (Documentation)：编译器强制要求可抛出函数和它们的调用侧都需要进行标注，这让程序员可以很容易看到哪里可能会发生错误。不过，类型系统并不会把一个函数所能抛出的错误类型暴露出来。


## 错误分类

预期中的错误：这些指的是那些在常规操作中，可以被程序员预见的失败情况。例如：网络连接问题 (网络连接永远都不可能是 100% 可靠的)，或用户输入内容不合法问题等。根据造成失败原因的复杂度，我们可以进一步把预期中的错误分成下面几类。

可以忽略细节的错误 (Trivial errors)：有些操作只有一个可以预期的失败情况。例如，查询字典的时候，结果只能是键值存在 (操作成功) 或不存在 (操作失败)。在 Swift 里，对于“不存在”或“不合法输入”这种简单且明确的日常错误条件，我们倾向于让函数返回可选值。因为返回一个包含详细信息的错误，并不会比可选值提供更多有效的信息。

需要提供详细信息的错误 (Rich errors)：对于网络和文件系统操作，它们应该提供关于失败情况的更多实质性问题描述，而不能只是一句简单的“有些东西工作不正常”而已。在这些场景里，造成失败的因素很多，程序员会根据不同的因素采用不同的处理方法 (例如：连接超时可能会重新发起请求，URL 不存在则会直接给用户错误提示)。这类错误是这一章接下来，我们主要关注的内容。

非预期错误：指的是那些在程序员预料之外的条件下导致的错误，这类错误通常会导致程序难以继续执行。通常这意味着程序员假定的一些 (“绝对不会发生的”) 条件被破坏了。例如，标准库就假设访问数组的下标不会越界，一个范围的上界不可能小于下界，整数不会溢出，以及除数不会为 0 等等。

在代码中，我们使用各种类型的断言 (例如：assert，precondition，或者 fatalError) 来确认期望的结果，并且在不满足条件的时候，让程序中断。在可选值章节中，我们见到过这些函数。断言是一个定位代码中 bug 的很棒的工具。正确使用它，一旦你的程序进入到了非预期的状态，它就能帮你定位到最早触发这个问题的位置。另外，它们还是一个很棒的文档工具：每个 assert 或 precondition 调用都是方法的作者对程序状态作出的一个 (隐性的) 假设，这些假设通过断言可以呈现给代码的读者。


## Result类型

在枚举这一章中，我们提到过，Result 是一个和 Optional 结构类似的枚举，它也包含两个成员，分别是：success 和 failure，它们的功能和 Optional 中的 some 和 none 是相同的。不同的是，Result.failure 也带有关联值，因此，Result 可以表达那些需要提供详细信息的错误

```
enum Result<Success, Failure: Error> {
	case success(Success)
	case failure(Failure)
}
```
要注意的是，Result 给表达失败情况的泛型参数添加了 Error 约束，表示这个 case 只用于表达错误

Optional 和 Result 的区别可以提示你究竟是否可以忽略错误的细节，还是必须要为错误提供额外的信息。我们就可以用 Optional 表达简单错误的方式，当需要表达具体错误信息的时候，来使用 Result。

```
enum FileError: Error {
	case fileDoesNotExist
	case noPermission
}

func contents(ofFile filename: String) -> Result<String, FileError>
```


## 抛出和捕获

Swift 内建的错误处理方式在很多方面都借鉴了上一节提到的 Result 的用法，只不过使用了不同的语法而已。Swift 没有使用返回 Result 的方式来表示失败，而是将方法标记为 throws。对于每个可以抛出错误的函数调用，编译器都会验证调用者有没有捕获错误，或者把这个错误向上传递给它调用者。把之前实现的 contents(ofFile:) 用 throws 语法表达出来是这样的
```
func contents(ofFile filename: String) throws -> String
```
现在，所有对 contents(ofFile:) 的调用都必须用关键字 try 标记，否则代码将无法编译。而这个 try 关键字无论对编译器还是代码的读者来说，都是一个信号，表明这个函数可能会抛出错误。

“调用一个可抛出错误的函数还会迫使我们决定如何处理错误。我们可以选择使用 do/catch 直接处理，或者把当前函数标记为 throws 将错误传递给调用栈上层的调用者。如果使用 catch 的话，可能会存在多条 catch 语句，我们可以用模式匹配来捕获某个特定的错误类型。在下面的例子中，我们显式地捕获了 fileDoesNotExist 的情况，并在最后的 catch-all 语句中处理其他所有错误。另外，在 catch-all 里，编译器还会自动生成一个 error 变量 (这一点和属性的 willSet 中的 newValue 很像)：”
```
do {
	let result = try contents(ofFile: "input.txt")
	print(result)
} catch FileError.fileDoesNotExist {
	print("File not found")
} catch {
	print(error)
	// 处理其它错误。
}
```

注意，我们也可以把一个结构体或者类作为错误类型来使用；任何遵守 Error 协议的类型都可以被函数作为错误抛出。而且由于 Error 协议中其实并没有任何要求，所以任何类型都可以声明遵守它，而并不需要添加任何额外的实现。
```
enum ParseError: Error {
	case wrongEncoding
	case warning(line: Int, message: String)
}

func parse(text: String) throws -> [String]

do {
	let result = try parse(text: "{ \"message\": \"We come in peace\" }")
	print(result)
} catch ParseError.wrongEncoding {
	print("Wrong encoding")
} catch let ParseError.warning(line, message) {
	print("Warning at line \(line): \(message)")
} catch {
	preconditionFailure("Unexpected error: \(error)")
}
```
其实，对于 Result 和 Swift 原生错误处理机制来说，无论是把成功和失败的情况分成不同的区域处理，还是在错误处理中，通过模式匹配区分执行路径以及绑定变量，这两种方法用起来的套路是非常相似的。当然，这并不是偶然，Swift 的错误处理方法本质上只是一层更漂亮的语法封装，本质上它要做的事情，还是创建并解包 Result”.
